Workbook

Sheet Program Economics
A1: Text-to-SQL Training Data Program Economics
A3: PROGRAM SCOPE
A4: Parameter | B4: Value | C4: Unit | D4: Notes
A5: Total Databases | B5: 100 | C5: databases | D5: Client target scope
A6: Queries per Database | B6: 30 | C6: queries/db | D6: Current standard
A7: Total Query Pairs | B7: =B5*B6 -> 3000 | C7: NL-SQL pairs | D7: =B5*B6 -> 3000
A8: Current Databases Delivered | B8: 16 | C8: databases | D8: db-1 through db-16
A9: Current Queries Delivered | B9: 452 | C9: queries | D9: Actual count
A10: Databases Requiring Rework | B10: 6 | C10: databases | D10: db-6,7,9,10,11,16 missing fields
A11: Remaining Databases | B11: =B5-B8 -> 84 | C11: databases | D11: =B5-B8 -> 84
A13: PER-QUERY EFFORT BREAKDOWN (Hours)
A14: Task Component | B14: Min Hours | C14: Likely Hours | D14: Max Hours | E14: Notes
A15: Schema comprehension & domain research | B15: 0.25 | C15: 0.5 | D15: 1 | E15: Understand tables, relationships, business context
A16: SQL query design & validation | B16: 0.5 | C16: 0.75 | D16: 1.5 | E16: Write, test, debug complex queries
A17: Business intent narrative (purpose) | B17: 0.25 | C17: 0.5 | D17: 0.75 | E17: Why a stakeholder needs this analysis
A18: Use case documentation | B18: 0.15 | C18: 0.25 | D18: 0.5 | E18: Who uses it, what decision it drives
A19: Business value articulation | B19: 0.15 | C19: 0.25 | D19: 0.5 | E19: Revenue/cost/risk impact quantified
A20: Expected output specification | B20: 0.1 | C20: 0.15 | D20: 0.25 | E20: Column descriptions, sample results
A21: Cross-query consistency review | B21: 0.1 | C21: 0.15 | D21: 0.25 | E21: Ensure no overlap, progressive complexity
A22: Quality assurance & formatting | B22: 0.15 | C22: 0.25 | D22: 0.5 | E22: JSON validation, style guide compliance
A23: TOTAL PER QUERY | B23: =SUM(B15:B22) -> 1.65 | C23: =SUM(C15:C22) -> 2.8 | D23: =SUM(D15:D22) -> 5.25
A24: TOTAL PER DATABASE (30 queries) | B24: =B23*B6 -> 49.5 | C24: =C23*B6 -> 84 | D24: =D23*B6 -> 157.5
A26: RATE ANALYSIS: STAFFING AGENCY vs CONSULTING
A27: Metric | B27: Staffing Agency | C27: Consulting | D27: Delta | E27: Notes
A28: Hourly Rate | B28: 100 | C28: 475 | D28: =C28-B28 -> 375 | E28: Market rates for 10yr tech professional
A29: Effective Daily Rate (8 hrs) | B29: =B28*8 -> 800 | C29: =C28*8 -> 3800 | D29: =C29-B29 -> 3000
A30: Per-Query Cost (likely hrs) | B30: =B28*C23 -> 280 | C30: =C28*C23 -> 1330 | D30: =C30-B30 -> 1050 | E30: Using "likely" hours estimate
A31: Per-Database Cost (30 queries) | B31: =B30*B6 -> 8400 | C31: =C30*B6 -> 39900 | D31: =C31-B31 -> 31500
A32: Full Program Cost (100 databases) | B32: =B31*B5 -> 840000 | C32: =C31*B5 -> 3990000 | D32: =C32-B32 -> 3150000
A33: Current Contract Value per DB | B33: 2000 | C33: 2000 | E33: Client offer: $2K per database
A34: Margin per Database (Staffing) | B34: =B33-B31 -> -6400
A35: Margin per Database (Consulting) | C35: =C33-C31 -> -37900
A36: Implied Hourly Rate at $2K/db | B36: =B33/C24 -> 23.809524 | E36: What client is actually paying per hour
A38: FULL PROGRAM COMPARISON
A39: Total Program Revenue (100 × $2K) | B39: =B33*B5 -> 200000 | C39: =C33*B5 -> 200000
A40: Total Program Cost | B40: =B32 -> 840000 | C40: =C32 -> 3990000
A41: Program Profit / (Loss) | B41: =B39-B40 -> -640000 | C41: =C39-C40 -> -3790000
A42: Program Margin % | B42: =IF(B39=0,0,B41/B39) -> -3.2 | C42: =IF(C39=0,0,C41/C39) -> -18.95
A44: INDUSTRY BENCHMARKS: Text-to-SQL Annotation Pricing
A45: Benchmark / Source | B45: Price per NL-SQL Pair | C45: Quality Tier | D45: Complexity | E45: Notes
...

Sheet Format Specification
A1: Recommended Deliverable JSON Schema — Text-to-SQL Training Format
A3: QUERY-LEVEL FIELDS (per entry in "queries" array)
A4: Field Name | B4: Type | C4: Required | D4: Description | E4: Maps to Benchmark
A5: number | B5: integer | C5: Yes | D5: Sequential query number within database (1-30) | E5: BIRD: —
A6: title | B6: string | C6: Yes | D6: Short descriptive title (5-10 words) | E6: Spider: question (partial)
A7: description | B7: string (300-500 chars) | C7: Yes | D7: Natural language question a business user would ask. Must read as a genuine stakeholder question, NOT a technical summary. | E7: BIRD: question / Spider: question
A8: purpose | B8: string (200-400 chars) | C8: Yes | D8: WHY this analysis matters — the business decision or action it enables. Written from stakeholder perspective. | E8: BIRD: evidence (extended)
A9: use_case | B9: string (150-300 chars) | C9: Yes | D9: WHO uses this and WHEN — specific role, department, cadence, and trigger for running the query. | E9: Semantic layer: context
A10: business_value | B10: string (150-300 chars) | C10: Yes | D10: Quantifiable or qualifiable impact — revenue, cost savings, risk reduction, efficiency gain. | E10: Semantic layer: ontology
A11: complexity | B11: enum | C11: Yes | D11: One of: basic, intermediate, advanced, expert. Based on SQL features used. | E11: BIRD: difficulty
A12: expected_output | B12: object | C12: Yes | D12: Schema of result set: column names, data types, sample values, row count estimate. | E12: Spider: db_id (implicit)
A13: sql | B13: string | C13: Yes | D13: Production-quality SQL. Must execute without errors on the provided schema. | E13: BIRD: SQL / Spider: query
A14: tags | B14: array[string] | C14: Recommended | D14: Classification tags: domain area, SQL features used, business function. | E14: BIRD: — (enhancement)
A15: evidence | B15: string | C15: Recommended | D15: Domain knowledge or business rules needed to understand the query (BIRD-compatible). | E15: BIRD: evidence
A18: CURRENT STATE vs RECOMMENDED STATE
A19: Field | B19: Well-Formed DBs (10) | C19: Broken DBs (6) | D19: Recommended Standard | E19: Action Required
A20: description | B20: 84-309 chars | C20: 500 chars (truncated) | D20: 300-500 chars, stakeholder voice | E20: Rewrite all — too short or truncated
A21: purpose | B21: Present | C21: MISSING | D21: Required 200-400 chars | E21: Add to 6 broken DBs, expand in 10
A22: use_case | B22: Present | C22: MISSING | D22: Required 150-300 chars | E22: Add to 6 broken DBs, expand in 10
A23: business_value | B23: Present | C23: MISSING | D23: Required 150-300 chars | E23: Add to 6 broken DBs, expand in 10
A24: line_number | B24: Absent | C24: Present | D24: REMOVE — not in spec | E24: Delete from all DBs
A25: tags | B25: Absent | C25: Absent | D25: Recommended — add | E25: New field across all DBs
A26: evidence | B26: Absent | C26: Absent | D26: Recommended (BIRD compat) | E26: New field across all DBs

Sheet Rework Estimate
A1: Rework & Remediation Cost for 16 Delivered Databases
A3: REWORK EFFORT
A4: Task | B4: Hours/Query | C4: Queries Affected | D4: Total Hours | E4: Cost @ $100/hr
A5: Rewrite descriptions (all 16 DBs) — stakeholder voice | B5: 0.5 | C5: 452 | D5: =B5*C5 -> 226 | E5: =D5*'Program Economics'!B28 -> 22600
A6: Add purpose field (6 broken DBs) | B6: 0.5 | C6: 180 | D6: =B6*C6 -> 90 | E6: =D6*'Program Economics'!B28 -> 9000
A7: Add use_case field (6 broken DBs) | B7: 0.25 | C7: 180 | D7: =B7*C7 -> 45 | E7: =D7*'Program Economics'!B28 -> 4500
A8: Add business_value field (6 broken DBs) | B8: 0.25 | C8: 180 | D8: =B8*C8 -> 45 | E8: =D8*'Program Economics'!B28 -> 4500
A9: Remove line_number, fix JSON structure | B9: 0.1 | C9: 180 | D9: =B9*C9 -> 18 | E9: =D9*'Program Economics'!B28 -> 1800
A10: Expand purpose/use_case/biz_value (10 well-formed DBs) | B10: 0.35 | C10: 272 | D10: =B10*C10 -> 95.2 | E10: =D10*'Program Economics'!B28 -> 9520
A11: Add tags field (all 16 DBs) | B11: 0.15 | C11: 452 | D11: =B11*C11 -> 67.8 | E11: =D11*'Program Economics'!B28 -> 6780
A12: Add evidence/domain context (all 16 DBs) | B12: 0.25 | C12: 452 | D12: =B12*C12 -> 113 | E12: =D12*'Program Economics'!B28 -> 11300
A13: QA & validation pass | B13: 0.1 | C13: 452 | D13: =B13*C13 -> 45.2 | E13: =D13*'Program Economics'!B28 -> 4520
A14: TOTAL REWORK | D14: =SUM(D5:D13) -> 745.2 | E14: =SUM(E5:E13) -> 74520
A15: TOTAL REWORK @ CONSULTING RATE ($475/hr) | E15: =D14*'Program Economics'!C28 -> 353970
A17: Revenue Earned (16 DBs × $2K) | E17: ='Program Economics'!B8*'Program Economics'!B33 -> 32000
A18: Net Position After Rework (Staffing Rate) | E18: =E17-E14 -> -42520
